[2017-01-13 22:02:37,298] pwnage101/INFO/helpers.settings: using settings file: /home/pwnage101/edx-load-tests/settings_files/lms.yml
[2017-01-13 22:02:37,301] pwnage101/INFO/helpers.settings: no secrets were specified in the settings file
[2017-01-13 22:02:37,301] pwnage101/INFO/helpers.settings: loaded the following public settings:
{'COURSE_DATA': 'demo_course',
 'COURSE_ID': 'course-v1:Fx+LT001+2015_T3',
 'LOCUST_MAX_WAIT': 1500,
 'LOCUST_MIN_WAIT': 750,
 'LOCUST_TASK_SET': 'LmsTest',
 'MODULE_RENDER_MODIFIER': 1,
 'PROCTORED_EXAM_MODIFIER': 1}
[2017-01-13 22:02:37,301] pwnage101/INFO/locust.main: Starting Locust 0.7.5
[2017-01-13 22:02:37,302] pwnage101/INFO/locust.runners: Hatching and swarming 385 clients at the rate 25 clients/s...
[2017-01-13 22:02:37,976] pwnage101/ERROR/stderr: Traceback (most recent call last):
  File "/home/pwnage101/edx-load-tests/venv/local/lib/python2.7/site-packages/locust/core.py", line 267, in run
    self.execute_next_task()
  File "/home/pwnage101/edx-load-tests/venv/local/lib/python2.7/site-packages/locust/core.py", line 293, in execute_next_task
    self.execute_task(task["callable"], *task["args"], **task["kwargs"])
  File "/home/pwnage101/edx-load-tests/venv/local/lib/python2.7/site-packages/locust/core.py", line 302, in execute_task
    task(self).run(*args, **kwargs)
  File "/home/pwnage101/edx-load-tests/venv/local/lib/python2.7/site-packages/locust/core.py", line 251, in run
    self.on_start()
  File "/home/pwnage101/edx-load-tests/loadtests/lms/proctoring.py", line 21, in on_start
    self.create_attempt()
  File "/home/pwnage101/edx-load-tests/loadtests/lms/proctoring.py", line 27, in create_attempt
    data = {'exam_id': self.course_data.exam_id, 'start_clock': True}
  File "/home/pwnage101/edx-load-tests/loadtests/lms/course_data/__init__.py", line 76, in exam_id
    return random.choice(self['special_exam_ids'])
KeyError: 'special_exam_ids'
[2017-01-13 22:02:40,413] pwnage101/ERROR/stderr: Traceback (most recent call last):
  File "/home/pwnage101/edx-load-tests/venv/local/lib/python2.7/site-packages/locust/core.py", line 267, in run
    self.execute_next_task()
  File "/home/pwnage101/edx-load-tests/venv/local/lib/python2.7/site-packages/locust/core.py", line 293, in execute_next_task
    self.execute_task(task["callable"], *task["args"], **task["kwargs"])
  File "/home/pwnage101/edx-load-tests/venv/local/lib/python2.7/site-packages/locust/core.py", line 302, in execute_task
    task(self).run(*args, **kwargs)
  File "/home/pwnage101/edx-load-tests/venv/local/lib/python2.7/site-packages/locust/core.py", line 251, in run
    self.on_start()
  File "/home/pwnage101/edx-load-tests/loadtests/lms/proctoring.py", line 21, in on_start
    self.create_attempt()
  File "/home/pwnage101/edx-load-tests/loadtests/lms/proctoring.py", line 27, in create_attempt
    data = {'exam_id': self.course_data.exam_id, 'start_clock': True}
  File "/home/pwnage101/edx-load-tests/loadtests/lms/course_data/__init__.py", line 76, in exam_id
    return random.choice(self['special_exam_ids'])
KeyError: 'special_exam_ids'
[2017-01-13 22:02:42,207] pwnage101/ERROR/stderr: Traceback (most recent call last):
  File "/home/pwnage101/edx-load-tests/venv/local/lib/python2.7/site-packages/locust/core.py", line 267, in run
    self.execute_next_task()
  File "/home/pwnage101/edx-load-tests/venv/local/lib/python2.7/site-packages/locust/core.py", line 293, in execute_next_task
    self.execute_task(task["callable"], *task["args"], **task["kwargs"])
  File "/home/pwnage101/edx-load-tests/venv/local/lib/python2.7/site-packages/locust/core.py", line 302, in execute_task
    task(self).run(*args, **kwargs)
  File "/home/pwnage101/edx-load-tests/venv/local/lib/python2.7/site-packages/locust/core.py", line 251, in run
    self.on_start()
  File "/home/pwnage101/edx-load-tests/loadtests/lms/proctoring.py", line 21, in on_start
    self.create_attempt()
  File "/home/pwnage101/edx-load-tests/loadtests/lms/proctoring.py", line 27, in create_attempt
    data = {'exam_id': self.course_data.exam_id, 'start_clock': True}
  File "/home/pwnage101/edx-load-tests/loadtests/lms/course_data/__init__.py", line 76, in exam_id
    return random.choice(self['special_exam_ids'])
KeyError: 'special_exam_ids'
[2017-01-13 22:02:42,549] pwnage101/ERROR/stderr: Traceback (most recent call last):
  File "/home/pwnage101/edx-load-tests/venv/local/lib/python2.7/site-packages/locust/core.py", line 267, in run
    self.execute_next_task()
  File "/home/pwnage101/edx-load-tests/venv/local/lib/python2.7/site-packages/locust/core.py", line 293, in execute_next_task
    self.execute_task(task["callable"], *task["args"], **task["kwargs"])
  File "/home/pwnage101/edx-load-tests/venv/local/lib/python2.7/site-packages/locust/core.py", line 302, in execute_task
    task(self).run(*args, **kwargs)
  File "/home/pwnage101/edx-load-tests/venv/local/lib/python2.7/site-packages/locust/core.py", line 251, in run
    self.on_start()
  File "/home/pwnage101/edx-load-tests/loadtests/lms/proctoring.py", line 21, in on_start
    self.create_attempt()
  File "/home/pwnage101/edx-load-tests/loadtests/lms/proctoring.py", line 27, in create_attempt
    data = {'exam_id': self.course_data.exam_id, 'start_clock': True}
  File "/home/pwnage101/edx-load-tests/loadtests/lms/course_data/__init__.py", line 76, in exam_id
    return random.choice(self['special_exam_ids'])
KeyError: 'special_exam_ids'
[2017-01-13 22:02:44,329] pwnage101/ERROR/stderr: Traceback (most recent call last):
  File "/home/pwnage101/edx-load-tests/venv/local/lib/python2.7/site-packages/locust/core.py", line 267, in run
    self.execute_next_task()
  File "/home/pwnage101/edx-load-tests/venv/local/lib/python2.7/site-packages/locust/core.py", line 293, in execute_next_task
    self.execute_task(task["callable"], *task["args"], **task["kwargs"])
  File "/home/pwnage101/edx-load-tests/venv/local/lib/python2.7/site-packages/locust/core.py", line 302, in execute_task
    task(self).run(*args, **kwargs)
  File "/home/pwnage101/edx-load-tests/venv/local/lib/python2.7/site-packages/locust/core.py", line 251, in run
    self.on_start()
  File "/home/pwnage101/edx-load-tests/loadtests/lms/proctoring.py", line 21, in on_start
    self.create_attempt()
  File "/home/pwnage101/edx-load-tests/loadtests/lms/proctoring.py", line 27, in create_attempt
    data = {'exam_id': self.course_data.exam_id, 'start_clock': True}
  File "/home/pwnage101/edx-load-tests/loadtests/lms/course_data/__init__.py", line 76, in exam_id
    return random.choice(self['special_exam_ids'])
KeyError: 'special_exam_ids'
[2017-01-13 22:02:49,072] pwnage101/ERROR/stderr: Traceback (most recent call last):
  File "/home/pwnage101/edx-load-tests/venv/local/lib/python2.7/site-packages/locust/core.py", line 267, in run
    self.execute_next_task()
  File "/home/pwnage101/edx-load-tests/venv/local/lib/python2.7/site-packages/locust/core.py", line 293, in execute_next_task
    self.execute_task(task["callable"], *task["args"], **task["kwargs"])
  File "/home/pwnage101/edx-load-tests/venv/local/lib/python2.7/site-packages/locust/core.py", line 302, in execute_task
    task(self).run(*args, **kwargs)
  File "/home/pwnage101/edx-load-tests/venv/local/lib/python2.7/site-packages/locust/core.py", line 251, in run
    self.on_start()
  File "/home/pwnage101/edx-load-tests/loadtests/lms/proctoring.py", line 21, in on_start
    self.create_attempt()
  File "/home/pwnage101/edx-load-tests/loadtests/lms/proctoring.py", line 27, in create_attempt
    data = {'exam_id': self.course_data.exam_id, 'start_clock': True}
  File "/home/pwnage101/edx-load-tests/loadtests/lms/course_data/__init__.py", line 76, in exam_id
    return random.choice(self['special_exam_ids'])
KeyError: 'special_exam_ids'
[2017-01-13 22:02:50,032] pwnage101/ERROR/stderr: Traceback (most recent call last):
  File "/home/pwnage101/edx-load-tests/venv/local/lib/python2.7/site-packages/locust/core.py", line 267, in run
    self.execute_next_task()
  File "/home/pwnage101/edx-load-tests/venv/local/lib/python2.7/site-packages/locust/core.py", line 293, in execute_next_task
    self.execute_task(task["callable"], *task["args"], **task["kwargs"])
  File "/home/pwnage101/edx-load-tests/venv/local/lib/python2.7/site-packages/locust/core.py", line 302, in execute_task
    task(self).run(*args, **kwargs)
  File "/home/pwnage101/edx-load-tests/venv/local/lib/python2.7/site-packages/locust/core.py", line 251, in run
    self.on_start()
  File "/home/pwnage101/edx-load-tests/loadtests/lms/proctoring.py", line 21, in on_start
    self.create_attempt()
  File "/home/pwnage101/edx-load-tests/loadtests/lms/proctoring.py", line 27, in create_attempt
    data = {'exam_id': self.course_data.exam_id, 'start_clock': True}
  File "/home/pwnage101/edx-load-tests/loadtests/lms/course_data/__init__.py", line 76, in exam_id
    return random.choice(self['special_exam_ids'])
KeyError: 'special_exam_ids'
[2017-01-13 22:02:50,761] pwnage101/ERROR/stderr: Traceback (most recent call last):
  File "/home/pwnage101/edx-load-tests/venv/local/lib/python2.7/site-packages/locust/core.py", line 267, in run
    self.execute_next_task()
  File "/home/pwnage101/edx-load-tests/venv/local/lib/python2.7/site-packages/locust/core.py", line 293, in execute_next_task
    self.execute_task(task["callable"], *task["args"], **task["kwargs"])
  File "/home/pwnage101/edx-load-tests/venv/local/lib/python2.7/site-packages/locust/core.py", line 302, in execute_task
    task(self).run(*args, **kwargs)
  File "/home/pwnage101/edx-load-tests/venv/local/lib/python2.7/site-packages/locust/core.py", line 251, in run
    self.on_start()
  File "/home/pwnage101/edx-load-tests/loadtests/lms/proctoring.py", line 21, in on_start
    self.create_attempt()
  File "/home/pwnage101/edx-load-tests/loadtests/lms/proctoring.py", line 27, in create_attempt
    data = {'exam_id': self.course_data.exam_id, 'start_clock': True}
  File "/home/pwnage101/edx-load-tests/loadtests/lms/course_data/__init__.py", line 76, in exam_id
    return random.choice(self['special_exam_ids'])
KeyError: 'special_exam_ids'
[2017-01-13 22:02:51,419] pwnage101/ERROR/stderr: Traceback (most recent call last):
  File "/home/pwnage101/edx-load-tests/venv/local/lib/python2.7/site-packages/locust/core.py", line 267, in run
    self.execute_next_task()
  File "/home/pwnage101/edx-load-tests/venv/local/lib/python2.7/site-packages/locust/core.py", line 293, in execute_next_task
    self.execute_task(task["callable"], *task["args"], **task["kwargs"])
  File "/home/pwnage101/edx-load-tests/venv/local/lib/python2.7/site-packages/locust/core.py", line 302, in execute_task
    task(self).run(*args, **kwargs)
  File "/home/pwnage101/edx-load-tests/venv/local/lib/python2.7/site-packages/locust/core.py", line 251, in run
    self.on_start()
  File "/home/pwnage101/edx-load-tests/loadtests/lms/proctoring.py", line 21, in on_start
    self.create_attempt()
  File "/home/pwnage101/edx-load-tests/loadtests/lms/proctoring.py", line 27, in create_attempt
    data = {'exam_id': self.course_data.exam_id, 'start_clock': True}
  File "/home/pwnage101/edx-load-tests/loadtests/lms/course_data/__init__.py", line 76, in exam_id
    return random.choice(self['special_exam_ids'])
KeyError: 'special_exam_ids'
[2017-01-13 22:02:53,015] pwnage101/ERROR/stderr: Traceback (most recent call last):
  File "/home/pwnage101/edx-load-tests/venv/local/lib/python2.7/site-packages/locust/core.py", line 267, in run
    self.execute_next_task()
  File "/home/pwnage101/edx-load-tests/venv/local/lib/python2.7/site-packages/locust/core.py", line 293, in execute_next_task
    self.execute_task(task["callable"], *task["args"], **task["kwargs"])
  File "/home/pwnage101/edx-load-tests/venv/local/lib/python2.7/site-packages/locust/core.py", line 302, in execute_task
    task(self).run(*args, **kwargs)
  File "/home/pwnage101/edx-load-tests/venv/local/lib/python2.7/site-packages/locust/core.py", line 251, in run
    self.on_start()
  File "/home/pwnage101/edx-load-tests/loadtests/lms/proctoring.py", line 21, in on_start
    self.create_attempt()
  File "/home/pwnage101/edx-load-tests/loadtests/lms/proctoring.py", line 27, in create_attempt
    data = {'exam_id': self.course_data.exam_id, 'start_clock': True}
  File "/home/pwnage101/edx-load-tests/loadtests/lms/course_data/__init__.py", line 76, in exam_id
    return random.choice(self['special_exam_ids'])
KeyError: 'special_exam_ids'
[2017-01-13 22:02:53,973] pwnage101/INFO/locust.runners: All locusts hatched: LmsLocust: 385
[2017-01-13 22:02:53,974] pwnage101/INFO/locust.runners: Resetting stats

[2017-01-13 22:12:37,032] pwnage101/INFO/locust.main: Got SIGTERM signal
[2017-01-13 22:12:37,032] pwnage101/INFO/locust.main: Shutting down (exit code 0), bye.
