[2017-01-13 22:23:17,476] pwnage101/INFO/helpers.settings: using settings file: /home/pwnage101/edx-load-tests/settings_files/lms.yml
[2017-01-13 22:23:17,479] pwnage101/INFO/helpers.settings: no secrets were specified in the settings file
[2017-01-13 22:23:17,479] pwnage101/INFO/helpers.settings: loaded the following public settings:
{'COURSE_DATA': 'demo_course',
 'COURSE_ID': 'course-v1:Fx+LT001+2015_T3',
 'LOCUST_MAX_WAIT': 1500,
 'LOCUST_MIN_WAIT': 750,
 'LOCUST_TASK_SET': 'LmsTest',
 'MODULE_RENDER_MODIFIER': 1,
 'PROCTORED_EXAM_MODIFIER': 1}
[2017-01-13 22:23:17,480] pwnage101/INFO/locust.main: Starting Locust 0.7.5
[2017-01-13 22:23:17,480] pwnage101/INFO/locust.runners: Hatching and swarming 495 clients at the rate 25 clients/s...
[2017-01-13 22:23:18,002] pwnage101/ERROR/stderr: Traceback (most recent call last):
  File "/home/pwnage101/edx-load-tests/venv/local/lib/python2.7/site-packages/locust/core.py", line 267, in run
    self.execute_next_task()
  File "/home/pwnage101/edx-load-tests/venv/local/lib/python2.7/site-packages/locust/core.py", line 293, in execute_next_task
    self.execute_task(task["callable"], *task["args"], **task["kwargs"])
  File "/home/pwnage101/edx-load-tests/venv/local/lib/python2.7/site-packages/locust/core.py", line 302, in execute_task
    task(self).run(*args, **kwargs)
  File "/home/pwnage101/edx-load-tests/venv/local/lib/python2.7/site-packages/locust/core.py", line 251, in run
    self.on_start()
  File "/home/pwnage101/edx-load-tests/loadtests/lms/proctoring.py", line 21, in on_start
    self.create_attempt()
  File "/home/pwnage101/edx-load-tests/loadtests/lms/proctoring.py", line 27, in create_attempt
    data = {'exam_id': self.course_data.exam_id, 'start_clock': True}
  File "/home/pwnage101/edx-load-tests/loadtests/lms/course_data/__init__.py", line 76, in exam_id
    return random.choice(self['special_exam_ids'])
KeyError: 'special_exam_ids'
[2017-01-13 22:23:18,464] pwnage101/ERROR/stderr: Traceback (most recent call last):
  File "/home/pwnage101/edx-load-tests/venv/local/lib/python2.7/site-packages/locust/core.py", line 267, in run
    self.execute_next_task()
  File "/home/pwnage101/edx-load-tests/venv/local/lib/python2.7/site-packages/locust/core.py", line 293, in execute_next_task
    self.execute_task(task["callable"], *task["args"], **task["kwargs"])
  File "/home/pwnage101/edx-load-tests/venv/local/lib/python2.7/site-packages/locust/core.py", line 302, in execute_task
    task(self).run(*args, **kwargs)
  File "/home/pwnage101/edx-load-tests/venv/local/lib/python2.7/site-packages/locust/core.py", line 251, in run
    self.on_start()
  File "/home/pwnage101/edx-load-tests/loadtests/lms/proctoring.py", line 21, in on_start
    self.create_attempt()
  File "/home/pwnage101/edx-load-tests/loadtests/lms/proctoring.py", line 27, in create_attempt
    data = {'exam_id': self.course_data.exam_id, 'start_clock': True}
  File "/home/pwnage101/edx-load-tests/loadtests/lms/course_data/__init__.py", line 76, in exam_id
    return random.choice(self['special_exam_ids'])
KeyError: 'special_exam_ids'
[2017-01-13 22:23:19,540] pwnage101/ERROR/stderr: Traceback (most recent call last):
  File "/home/pwnage101/edx-load-tests/venv/local/lib/python2.7/site-packages/locust/core.py", line 267, in run
    self.execute_next_task()
  File "/home/pwnage101/edx-load-tests/venv/local/lib/python2.7/site-packages/locust/core.py", line 293, in execute_next_task
    self.execute_task(task["callable"], *task["args"], **task["kwargs"])
  File "/home/pwnage101/edx-load-tests/venv/local/lib/python2.7/site-packages/locust/core.py", line 302, in execute_task
    task(self).run(*args, **kwargs)
  File "/home/pwnage101/edx-load-tests/venv/local/lib/python2.7/site-packages/locust/core.py", line 251, in run
    self.on_start()
  File "/home/pwnage101/edx-load-tests/loadtests/lms/proctoring.py", line 21, in on_start
    self.create_attempt()
  File "/home/pwnage101/edx-load-tests/loadtests/lms/proctoring.py", line 27, in create_attempt
    data = {'exam_id': self.course_data.exam_id, 'start_clock': True}
  File "/home/pwnage101/edx-load-tests/loadtests/lms/course_data/__init__.py", line 76, in exam_id
    return random.choice(self['special_exam_ids'])
KeyError: 'special_exam_ids'
[2017-01-13 22:23:19,774] pwnage101/ERROR/stderr: Traceback (most recent call last):
  File "/home/pwnage101/edx-load-tests/venv/local/lib/python2.7/site-packages/locust/core.py", line 267, in run
    self.execute_next_task()
  File "/home/pwnage101/edx-load-tests/venv/local/lib/python2.7/site-packages/locust/core.py", line 293, in execute_next_task
    self.execute_task(task["callable"], *task["args"], **task["kwargs"])
  File "/home/pwnage101/edx-load-tests/venv/local/lib/python2.7/site-packages/locust/core.py", line 302, in execute_task
    task(self).run(*args, **kwargs)
  File "/home/pwnage101/edx-load-tests/venv/local/lib/python2.7/site-packages/locust/core.py", line 251, in run
    self.on_start()
  File "/home/pwnage101/edx-load-tests/loadtests/lms/proctoring.py", line 21, in on_start
    self.create_attempt()
  File "/home/pwnage101/edx-load-tests/loadtests/lms/proctoring.py", line 27, in create_attempt
    data = {'exam_id': self.course_data.exam_id, 'start_clock': True}
  File "/home/pwnage101/edx-load-tests/loadtests/lms/course_data/__init__.py", line 76, in exam_id
    return random.choice(self['special_exam_ids'])
KeyError: 'special_exam_ids'
[2017-01-13 22:23:21,381] pwnage101/ERROR/stderr: Traceback (most recent call last):
  File "/home/pwnage101/edx-load-tests/venv/local/lib/python2.7/site-packages/locust/core.py", line 267, in run
    self.execute_next_task()
  File "/home/pwnage101/edx-load-tests/venv/local/lib/python2.7/site-packages/locust/core.py", line 293, in execute_next_task
    self.execute_task(task["callable"], *task["args"], **task["kwargs"])
  File "/home/pwnage101/edx-load-tests/venv/local/lib/python2.7/site-packages/locust/core.py", line 302, in execute_task
    task(self).run(*args, **kwargs)
  File "/home/pwnage101/edx-load-tests/venv/local/lib/python2.7/site-packages/locust/core.py", line 251, in run
    self.on_start()
  File "/home/pwnage101/edx-load-tests/loadtests/lms/proctoring.py", line 21, in on_start
    self.create_attempt()
  File "/home/pwnage101/edx-load-tests/loadtests/lms/proctoring.py", line 27, in create_attempt
    data = {'exam_id': self.course_data.exam_id, 'start_clock': True}
  File "/home/pwnage101/edx-load-tests/loadtests/lms/course_data/__init__.py", line 76, in exam_id
    return random.choice(self['special_exam_ids'])
KeyError: 'special_exam_ids'
[2017-01-13 22:23:26,530] pwnage101/ERROR/stderr: Traceback (most recent call last):
  File "/home/pwnage101/edx-load-tests/venv/local/lib/python2.7/site-packages/locust/core.py", line 267, in run
    self.execute_next_task()
  File "/home/pwnage101/edx-load-tests/venv/local/lib/python2.7/site-packages/locust/core.py", line 293, in execute_next_task
    self.execute_task(task["callable"], *task["args"], **task["kwargs"])
  File "/home/pwnage101/edx-load-tests/venv/local/lib/python2.7/site-packages/locust/core.py", line 302, in execute_task
    task(self).run(*args, **kwargs)
  File "/home/pwnage101/edx-load-tests/venv/local/lib/python2.7/site-packages/locust/core.py", line 251, in run
    self.on_start()
  File "/home/pwnage101/edx-load-tests/loadtests/lms/proctoring.py", line 21, in on_start
    self.create_attempt()
  File "/home/pwnage101/edx-load-tests/loadtests/lms/proctoring.py", line 27, in create_attempt
    data = {'exam_id': self.course_data.exam_id, 'start_clock': True}
  File "/home/pwnage101/edx-load-tests/loadtests/lms/course_data/__init__.py", line 76, in exam_id
    return random.choice(self['special_exam_ids'])
KeyError: 'special_exam_ids'
[2017-01-13 22:23:30,319] pwnage101/ERROR/stderr: Traceback (most recent call last):
  File "/home/pwnage101/edx-load-tests/venv/local/lib/python2.7/site-packages/locust/core.py", line 267, in run
    self.execute_next_task()
  File "/home/pwnage101/edx-load-tests/venv/local/lib/python2.7/site-packages/locust/core.py", line 293, in execute_next_task
    self.execute_task(task["callable"], *task["args"], **task["kwargs"])
  File "/home/pwnage101/edx-load-tests/venv/local/lib/python2.7/site-packages/locust/core.py", line 302, in execute_task
    task(self).run(*args, **kwargs)
  File "/home/pwnage101/edx-load-tests/venv/local/lib/python2.7/site-packages/locust/core.py", line 251, in run
    self.on_start()
  File "/home/pwnage101/edx-load-tests/loadtests/lms/proctoring.py", line 21, in on_start
    self.create_attempt()
  File "/home/pwnage101/edx-load-tests/loadtests/lms/proctoring.py", line 27, in create_attempt
    data = {'exam_id': self.course_data.exam_id, 'start_clock': True}
  File "/home/pwnage101/edx-load-tests/loadtests/lms/course_data/__init__.py", line 76, in exam_id
    return random.choice(self['special_exam_ids'])
KeyError: 'special_exam_ids'
[2017-01-13 22:23:40,105] pwnage101/ERROR/stderr: Traceback (most recent call last):
  File "/home/pwnage101/edx-load-tests/venv/local/lib/python2.7/site-packages/locust/core.py", line 267, in run
    self.execute_next_task()
  File "/home/pwnage101/edx-load-tests/venv/local/lib/python2.7/site-packages/locust/core.py", line 293, in execute_next_task
    self.execute_task(task["callable"], *task["args"], **task["kwargs"])
  File "/home/pwnage101/edx-load-tests/venv/local/lib/python2.7/site-packages/locust/core.py", line 302, in execute_task
    task(self).run(*args, **kwargs)
  File "/home/pwnage101/edx-load-tests/venv/local/lib/python2.7/site-packages/locust/core.py", line 251, in run
    self.on_start()
  File "/home/pwnage101/edx-load-tests/loadtests/lms/proctoring.py", line 21, in on_start
    self.create_attempt()
  File "/home/pwnage101/edx-load-tests/loadtests/lms/proctoring.py", line 27, in create_attempt
    data = {'exam_id': self.course_data.exam_id, 'start_clock': True}
  File "/home/pwnage101/edx-load-tests/loadtests/lms/course_data/__init__.py", line 76, in exam_id
    return random.choice(self['special_exam_ids'])
KeyError: 'special_exam_ids'
[2017-01-13 22:23:40,311] pwnage101/INFO/locust.runners: All locusts hatched: LmsLocust: 495
[2017-01-13 22:23:40,312] pwnage101/INFO/locust.runners: Resetting stats

[2017-01-13 22:31:25,627] pwnage101/ERROR/stderr: Traceback (most recent call last):
  File "/home/pwnage101/edx-load-tests/venv/local/lib/python2.7/site-packages/locust/core.py", line 267, in run
    self.execute_next_task()
  File "/home/pwnage101/edx-load-tests/venv/local/lib/python2.7/site-packages/locust/core.py", line 293, in execute_next_task
    self.execute_task(task["callable"], *task["args"], **task["kwargs"])
  File "/home/pwnage101/edx-load-tests/venv/local/lib/python2.7/site-packages/locust/core.py", line 305, in execute_task
    task(self, *args, **kwargs)
  File "/home/pwnage101/edx-load-tests/loadtests/lms/forums.py", line 224, in create_thread
    thread = super(ForumsTasks, self).create_thread(self.random_topic_id(), name='forums:create_thread')
  File "/home/pwnage101/edx-load-tests/loadtests/lms/forums.py", line 109, in create_thread
    thread_id = response.json()['id']
KeyError: 'id'
[2017-01-13 22:33:17,203] pwnage101/INFO/locust.main: Got SIGTERM signal
[2017-01-13 22:33:17,203] pwnage101/INFO/locust.main: Shutting down (exit code 0), bye.
