[2017-01-18 18:39:49,530] pwnage101/INFO/helpers.settings: using settings file: /home/pwnage101/edx-load-tests/settings_files/lms.yml
[2017-01-18 18:39:49,533] pwnage101/INFO/helpers.settings: no secrets were specified in the settings file
[2017-01-18 18:39:49,534] pwnage101/INFO/helpers.settings: loaded the following public settings:
{'COURSE_DATA': 'demo_course',
 'COURSE_ID': 'course-v1:Fx+LT001+2015_T3',
 'LOCUST_MAX_WAIT': 1000,
 'LOCUST_MIN_WAIT': 300,
 'LOCUST_TASK_SET': 'LmsTest',
 'MODULE_RENDER_MODIFIER': 1,
 'PROCTORED_EXAM_MODIFIER': 1}
[2017-01-18 18:39:49,534] pwnage101/INFO/locust.main: Starting Locust 0.7.5
[2017-01-18 18:39:49,534] pwnage101/INFO/locust.runners: Hatching and swarming 245 clients at the rate 25 clients/s...
[2017-01-18 18:39:53,361] pwnage101/ERROR/stderr: Traceback (most recent call last):
  File "/home/pwnage101/edx-load-tests/venv/local/lib/python2.7/site-packages/locust/core.py", line 267, in run
    self.execute_next_task()
  File "/home/pwnage101/edx-load-tests/venv/local/lib/python2.7/site-packages/locust/core.py", line 293, in execute_next_task
    self.execute_task(task["callable"], *task["args"], **task["kwargs"])
  File "/home/pwnage101/edx-load-tests/venv/local/lib/python2.7/site-packages/locust/core.py", line 302, in execute_task
    task(self).run(*args, **kwargs)
  File "/home/pwnage101/edx-load-tests/venv/local/lib/python2.7/site-packages/locust/core.py", line 251, in run
    self.on_start()
  File "/home/pwnage101/edx-load-tests/loadtests/lms/proctoring.py", line 21, in on_start
    self.create_attempt()
  File "/home/pwnage101/edx-load-tests/loadtests/lms/proctoring.py", line 27, in create_attempt
    data = {'exam_id': self.course_data.exam_id, 'start_clock': True}
  File "/home/pwnage101/edx-load-tests/loadtests/lms/course_data/__init__.py", line 76, in exam_id
    return random.choice(self['special_exam_ids'])
KeyError: 'special_exam_ids'
[2017-01-18 18:39:53,450] pwnage101/ERROR/stderr: Traceback (most recent call last):
  File "/home/pwnage101/edx-load-tests/venv/local/lib/python2.7/site-packages/locust/core.py", line 267, in run
    self.execute_next_task()
  File "/home/pwnage101/edx-load-tests/venv/local/lib/python2.7/site-packages/locust/core.py", line 293, in execute_next_task
    self.execute_task(task["callable"], *task["args"], **task["kwargs"])
  File "/home/pwnage101/edx-load-tests/venv/local/lib/python2.7/site-packages/locust/core.py", line 302, in execute_task
    task(self).run(*args, **kwargs)
  File "/home/pwnage101/edx-load-tests/venv/local/lib/python2.7/site-packages/locust/core.py", line 251, in run
    self.on_start()
  File "/home/pwnage101/edx-load-tests/loadtests/lms/proctoring.py", line 21, in on_start
    self.create_attempt()
  File "/home/pwnage101/edx-load-tests/loadtests/lms/proctoring.py", line 27, in create_attempt
    data = {'exam_id': self.course_data.exam_id, 'start_clock': True}
  File "/home/pwnage101/edx-load-tests/loadtests/lms/course_data/__init__.py", line 76, in exam_id
    return random.choice(self['special_exam_ids'])
KeyError: 'special_exam_ids'
[2017-01-18 18:39:58,152] pwnage101/ERROR/stderr: Traceback (most recent call last):
  File "/home/pwnage101/edx-load-tests/venv/local/lib/python2.7/site-packages/locust/core.py", line 267, in run
    self.execute_next_task()
  File "/home/pwnage101/edx-load-tests/venv/local/lib/python2.7/site-packages/locust/core.py", line 293, in execute_next_task
    self.execute_task(task["callable"], *task["args"], **task["kwargs"])
  File "/home/pwnage101/edx-load-tests/venv/local/lib/python2.7/site-packages/locust/core.py", line 302, in execute_task
    task(self).run(*args, **kwargs)
  File "/home/pwnage101/edx-load-tests/venv/local/lib/python2.7/site-packages/locust/core.py", line 251, in run
    self.on_start()
  File "/home/pwnage101/edx-load-tests/loadtests/lms/proctoring.py", line 21, in on_start
    self.create_attempt()
  File "/home/pwnage101/edx-load-tests/loadtests/lms/proctoring.py", line 27, in create_attempt
    data = {'exam_id': self.course_data.exam_id, 'start_clock': True}
  File "/home/pwnage101/edx-load-tests/loadtests/lms/course_data/__init__.py", line 76, in exam_id
    return random.choice(self['special_exam_ids'])
KeyError: 'special_exam_ids'
[2017-01-18 18:39:58,602] pwnage101/ERROR/stderr: Traceback (most recent call last):
  File "/home/pwnage101/edx-load-tests/venv/local/lib/python2.7/site-packages/locust/core.py", line 267, in run
    self.execute_next_task()
  File "/home/pwnage101/edx-load-tests/venv/local/lib/python2.7/site-packages/locust/core.py", line 293, in execute_next_task
    self.execute_task(task["callable"], *task["args"], **task["kwargs"])
  File "/home/pwnage101/edx-load-tests/venv/local/lib/python2.7/site-packages/locust/core.py", line 302, in execute_task
    task(self).run(*args, **kwargs)
  File "/home/pwnage101/edx-load-tests/venv/local/lib/python2.7/site-packages/locust/core.py", line 251, in run
    self.on_start()
  File "/home/pwnage101/edx-load-tests/loadtests/lms/proctoring.py", line 21, in on_start
    self.create_attempt()
  File "/home/pwnage101/edx-load-tests/loadtests/lms/proctoring.py", line 27, in create_attempt
    data = {'exam_id': self.course_data.exam_id, 'start_clock': True}
  File "/home/pwnage101/edx-load-tests/loadtests/lms/course_data/__init__.py", line 76, in exam_id
    return random.choice(self['special_exam_ids'])
KeyError: 'special_exam_ids'
[2017-01-18 18:39:59,847] pwnage101/ERROR/stderr: Traceback (most recent call last):
  File "/home/pwnage101/edx-load-tests/venv/local/lib/python2.7/site-packages/locust/core.py", line 267, in run
    self.execute_next_task()
  File "/home/pwnage101/edx-load-tests/venv/local/lib/python2.7/site-packages/locust/core.py", line 293, in execute_next_task
    self.execute_task(task["callable"], *task["args"], **task["kwargs"])
  File "/home/pwnage101/edx-load-tests/venv/local/lib/python2.7/site-packages/locust/core.py", line 302, in execute_task
    task(self).run(*args, **kwargs)
  File "/home/pwnage101/edx-load-tests/venv/local/lib/python2.7/site-packages/locust/core.py", line 251, in run
    self.on_start()
  File "/home/pwnage101/edx-load-tests/loadtests/lms/proctoring.py", line 21, in on_start
    self.create_attempt()
  File "/home/pwnage101/edx-load-tests/loadtests/lms/proctoring.py", line 27, in create_attempt
    data = {'exam_id': self.course_data.exam_id, 'start_clock': True}
  File "/home/pwnage101/edx-load-tests/loadtests/lms/course_data/__init__.py", line 76, in exam_id
    return random.choice(self['special_exam_ids'])
KeyError: 'special_exam_ids'
[2017-01-18 18:40:00,120] pwnage101/INFO/locust.runners: All locusts hatched: LmsLocust: 245
[2017-01-18 18:40:00,120] pwnage101/INFO/locust.runners: Resetting stats

[2017-01-18 18:49:49,262] pwnage101/INFO/locust.main: Got SIGTERM signal
[2017-01-18 18:49:49,262] pwnage101/INFO/locust.main: Shutting down (exit code 0), bye.
