[2017-02-14 18:47:03,091] pwnage101/INFO/helpers.settings: using settings file: /home/pwnage101/edx-load-tests/settings_files/lms.yml
[2017-02-14 18:47:03,095] pwnage101/INFO/helpers.settings: no secrets were specified in the settings file
[2017-02-14 18:47:03,095] pwnage101/INFO/helpers.settings: loaded the following public settings:
{'LOCUST_MAX_WAIT': 1000,
 'LOCUST_MIN_WAIT': 300,
 'LOCUST_TASK_SET': 'LmsTest',
 'MODULE_RENDER_MODIFIER': 1,
 'PROCTORED_EXAM_MODIFIER': 1,
 'courses': {'course-v1:Fx+LT001+2015_T3': {'course_data': 'demo_course_feanil',
                                            'ratio': 1},
             'edX/DemoX/Demo_Course': {'course_data': 'demo_course',
                                       'ratio': 1}}}
[2017-02-14 18:47:03,095] pwnage101/INFO/locust.main: Starting Locust 0.7.5
[2017-02-14 18:47:03,096] pwnage101/INFO/locust.runners: Hatching and swarming 350 clients at the rate 25 clients/s...
[2017-02-14 18:47:05,285] pwnage101/ERROR/stderr: Traceback (most recent call last):
  File "/home/pwnage101/edx-load-tests/venv/local/lib/python2.7/site-packages/locust/core.py", line 267, in run
    self.execute_next_task()
  File "/home/pwnage101/edx-load-tests/venv/local/lib/python2.7/site-packages/locust/core.py", line 293, in execute_next_task
    self.execute_task(task["callable"], *task["args"], **task["kwargs"])
  File "/home/pwnage101/edx-load-tests/venv/local/lib/python2.7/site-packages/locust/core.py", line 302, in execute_task
    task(self).run(*args, **kwargs)
  File "/home/pwnage101/edx-load-tests/venv/local/lib/python2.7/site-packages/locust/core.py", line 251, in run
    self.on_start()
  File "/home/pwnage101/edx-load-tests/loadtests/lms/proctoring.py", line 21, in on_start
    self.create_attempt()
  File "/home/pwnage101/edx-load-tests/loadtests/lms/proctoring.py", line 27, in create_attempt
    data = {'exam_id': self.course_data.exam_id, 'start_clock': True}
  File "/home/pwnage101/edx-load-tests/loadtests/lms/course_data/__init__.py", line 76, in exam_id
    return random.choice(self['special_exam_ids'])
KeyError: 'special_exam_ids'
[2017-02-14 18:47:07,329] pwnage101/ERROR/stderr: Traceback (most recent call last):
  File "/home/pwnage101/edx-load-tests/venv/local/lib/python2.7/site-packages/locust/core.py", line 267, in run
    self.execute_next_task()
  File "/home/pwnage101/edx-load-tests/venv/local/lib/python2.7/site-packages/locust/core.py", line 293, in execute_next_task
    self.execute_task(task["callable"], *task["args"], **task["kwargs"])
  File "/home/pwnage101/edx-load-tests/venv/local/lib/python2.7/site-packages/locust/core.py", line 302, in execute_task
    task(self).run(*args, **kwargs)
  File "/home/pwnage101/edx-load-tests/venv/local/lib/python2.7/site-packages/locust/core.py", line 251, in run
    self.on_start()
  File "/home/pwnage101/edx-load-tests/loadtests/lms/proctoring.py", line 21, in on_start
    self.create_attempt()
  File "/home/pwnage101/edx-load-tests/loadtests/lms/proctoring.py", line 27, in create_attempt
    data = {'exam_id': self.course_data.exam_id, 'start_clock': True}
  File "/home/pwnage101/edx-load-tests/loadtests/lms/course_data/__init__.py", line 76, in exam_id
    return random.choice(self['special_exam_ids'])
KeyError: 'special_exam_ids'
[2017-02-14 18:47:07,466] pwnage101/ERROR/stderr: Traceback (most recent call last):
  File "/home/pwnage101/edx-load-tests/venv/local/lib/python2.7/site-packages/locust/core.py", line 267, in run
    self.execute_next_task()
  File "/home/pwnage101/edx-load-tests/venv/local/lib/python2.7/site-packages/locust/core.py", line 293, in execute_next_task
    self.execute_task(task["callable"], *task["args"], **task["kwargs"])
  File "/home/pwnage101/edx-load-tests/venv/local/lib/python2.7/site-packages/locust/core.py", line 302, in execute_task
    task(self).run(*args, **kwargs)
  File "/home/pwnage101/edx-load-tests/venv/local/lib/python2.7/site-packages/locust/core.py", line 251, in run
    self.on_start()
  File "/home/pwnage101/edx-load-tests/loadtests/lms/proctoring.py", line 21, in on_start
    self.create_attempt()
  File "/home/pwnage101/edx-load-tests/loadtests/lms/proctoring.py", line 27, in create_attempt
    data = {'exam_id': self.course_data.exam_id, 'start_clock': True}
  File "/home/pwnage101/edx-load-tests/loadtests/lms/course_data/__init__.py", line 76, in exam_id
    return random.choice(self['special_exam_ids'])
KeyError: 'special_exam_ids'
[2017-02-14 18:47:19,410] pwnage101/ERROR/stderr: Traceback (most recent call last):
  File "/home/pwnage101/edx-load-tests/venv/local/lib/python2.7/site-packages/locust/core.py", line 267, in run
    self.execute_next_task()
  File "/home/pwnage101/edx-load-tests/venv/local/lib/python2.7/site-packages/locust/core.py", line 293, in execute_next_task
    self.execute_task(task["callable"], *task["args"], **task["kwargs"])
  File "/home/pwnage101/edx-load-tests/venv/local/lib/python2.7/site-packages/locust/core.py", line 302, in execute_task
    task(self).run(*args, **kwargs)
  File "/home/pwnage101/edx-load-tests/venv/local/lib/python2.7/site-packages/locust/core.py", line 251, in run
    self.on_start()
  File "/home/pwnage101/edx-load-tests/loadtests/lms/proctoring.py", line 21, in on_start
    self.create_attempt()
  File "/home/pwnage101/edx-load-tests/loadtests/lms/proctoring.py", line 27, in create_attempt
    data = {'exam_id': self.course_data.exam_id, 'start_clock': True}
  File "/home/pwnage101/edx-load-tests/loadtests/lms/course_data/__init__.py", line 76, in exam_id
    return random.choice(self['special_exam_ids'])
KeyError: 'special_exam_ids'
[2017-02-14 18:47:19,522] pwnage101/INFO/locust.runners: All locusts hatched: LmsLocust: 350
[2017-02-14 18:47:19,523] pwnage101/INFO/locust.runners: Resetting stats

[2017-02-14 18:53:55,641] pwnage101/ERROR/stderr: Traceback (most recent call last):
  File "/home/pwnage101/edx-load-tests/venv/local/lib/python2.7/site-packages/locust/core.py", line 267, in run
    self.execute_next_task()
  File "/home/pwnage101/edx-load-tests/venv/local/lib/python2.7/site-packages/locust/core.py", line 293, in execute_next_task
    self.execute_task(task["callable"], *task["args"], **task["kwargs"])
  File "/home/pwnage101/edx-load-tests/venv/local/lib/python2.7/site-packages/locust/core.py", line 305, in execute_task
    task(self, *args, **kwargs)
  File "/home/pwnage101/edx-load-tests/loadtests/lms/forums.py", line 230, in create_thread
    thread = super(ForumsTasks, self).create_thread(self.random_topic_id(), name='forums:create_thread')
  File "/home/pwnage101/edx-load-tests/loadtests/lms/forums.py", line 115, in create_thread
    thread_id = response.json()['id']
  File "/home/pwnage101/edx-load-tests/venv/local/lib/python2.7/site-packages/requests/models.py", line 866, in json
    return complexjson.loads(self.text, **kwargs)
  File "/home/pwnage101/edx-load-tests/venv/local/lib/python2.7/site-packages/simplejson/__init__.py", line 516, in loads
    return _default_decoder.decode(s)
  File "/home/pwnage101/edx-load-tests/venv/local/lib/python2.7/site-packages/simplejson/decoder.py", line 374, in decode
    obj, end = self.raw_decode(s)
  File "/home/pwnage101/edx-load-tests/venv/local/lib/python2.7/site-packages/simplejson/decoder.py", line 404, in raw_decode
    return self.scan_once(s, idx=_w(s, idx).end())
JSONDecodeError: Expecting value: line 9 column 1 (char 8)
[2017-02-14 18:54:45,704] pwnage101/ERROR/stderr: Traceback (most recent call last):
  File "/home/pwnage101/edx-load-tests/venv/local/lib/python2.7/site-packages/locust/core.py", line 267, in run
    self.execute_next_task()
  File "/home/pwnage101/edx-load-tests/venv/local/lib/python2.7/site-packages/locust/core.py", line 293, in execute_next_task
    self.execute_task(task["callable"], *task["args"], **task["kwargs"])
  File "/home/pwnage101/edx-load-tests/venv/local/lib/python2.7/site-packages/locust/core.py", line 305, in execute_task
    task(self, *args, **kwargs)
  File "/home/pwnage101/edx-load-tests/loadtests/lms/forums.py", line 230, in create_thread
    thread = super(ForumsTasks, self).create_thread(self.random_topic_id(), name='forums:create_thread')
  File "/home/pwnage101/edx-load-tests/loadtests/lms/forums.py", line 115, in create_thread
    thread_id = response.json()['id']
KeyError: 'id'
[2017-02-14 18:57:02,818] pwnage101/INFO/locust.main: Got SIGTERM signal
[2017-02-14 18:57:02,819] pwnage101/INFO/locust.main: Shutting down (exit code 0), bye.
